# Goxel 0.7.3
# One line per voxel
# X Y Z RRGGBB
0 0 0 ffffff
1 0 0 ffffff
2 0 0 ffffff
3 0 0 ffffff
4 0 0 ffffff
5 0 0 ffffff
6 0 0 ffffff
7 0 0 ffffff
8 0 0 ffffff
9 0 0 ffffff
0 1 0 ffffff
1 1 0 ffffff
2 1 0 ffffff
3 1 0 ffffff
4 1 0 ffffff
5 1 0 ffffff
6 1 0 ffffff
7 1 0 ffffff
8 1 0 ffffff
9 1 0 ffffff
0 2 0 ffffff
1 2 0 ffffff
2 2 0 ffffff
3 2 0 ffffff
4 2 0 ffffff
5 2 0 ffffff
6 2 0 ffffff
7 2 0 ffffff
8 2 0 ffffff
9 2 0 ffffff
0 3 0 ffffff
1 3 0 ffffff
2 3 0 ffffff
3 3 0 ffffff
4 3 0 ffffff
5 3 0 ffffff
6 3 0 ffffff
7 3 0 ffffff
8 3 0 ffffff
9 3 0 ffffff
0 4 0 ffffff
1 4 0 ffffff
2 4 0 ffffff
3 4 0 ffffff
4 4 0 ffffff
5 4 0 ffffff
6 4 0 ffffff
7 4 0 ffffff
8 4 0 ffffff
9 4 0 ffffff
0 5 0 ffffff
1 5 0 ffffff
2 5 0 ffffff
3 5 0 ffffff
4 5 0 ffffff
5 5 0 ffffff
6 5 0 ffffff
7 5 0 ffffff
8 5 0 ffffff
9 5 0 ffffff
0 6 0 ffffff
1 6 0 ffffff
2 6 0 ffffff
3 6 0 ffffff
4 6 0 ffffff
5 6 0 ffffff
6 6 0 ffffff
7 6 0 ffffff
8 6 0 ffffff
9 6 0 ffffff
0 7 0 ffffff
1 7 0 ffffff
2 7 0 ffffff
3 7 0 ffffff
4 7 0 ffffff
5 7 0 ffffff
6 7 0 ffffff
7 7 0 ffffff
8 7 0 ffffff
9 7 0 ffffff
0 8 0 ffffff
1 8 0 ffffff
2 8 0 ffffff
3 8 0 ffffff
4 8 0 ffffff
5 8 0 ffffff
6 8 0 ffffff
7 8 0 ffffff
8 8 0 ffffff
9 8 0 ffffff
0 9 0 ffffff
1 9 0 ffffff
2 9 0 ffffff
3 9 0 ffffff
4 9 0 ffffff
5 9 0 ffffff
6 9 0 ffffff
7 9 0 ffffff
8 9 0 ffffff
9 9 0 ffffff
0 0 1 ffffff
1 0 1 ffffff
2 0 1 ffffff
3 0 1 ffffff
4 0 1 ffffff
5 0 1 ffffff
6 0 1 ffffff
7 0 1 ffffff
8 0 1 ffffff
9 0 1 ffffff
0 1 1 ffffff
1 1 1 ffffff
2 1 1 ffffff
3 1 1 ffffff
4 1 1 ffffff
5 1 1 ffffff
6 1 1 ffffff
7 1 1 ffffff
8 1 1 ffffff
9 1 1 ffffff
0 2 1 ffffff
1 2 1 ffffff
2 2 1 ffffff
3 2 1 ffffff
4 2 1 ffffff
5 2 1 ffffff
6 2 1 ffffff
7 2 1 ffffff
8 2 1 ffffff
9 2 1 ffffff
0 3 1 ffffff
1 3 1 ffffff
2 3 1 ffffff
3 3 1 ffffff
4 3 1 ffffff
5 3 1 ffffff
6 3 1 ffffff
7 3 1 ffffff
8 3 1 ffffff
9 3 1 ffffff
0 4 1 ffffff
1 4 1 ffffff
2 4 1 ffffff
3 4 1 ffffff
4 4 1 ffffff
5 4 1 ffffff
6 4 1 ffffff
7 4 1 ffffff
8 4 1 ffffff
9 4 1 ffffff
0 5 1 ffffff
1 5 1 ffffff
2 5 1 ffffff
3 5 1 ffffff
4 5 1 ffffff
5 5 1 ffffff
6 5 1 ffffff
7 5 1 ffffff
8 5 1 ffffff
9 5 1 ffffff
0 6 1 ffffff
1 6 1 ffffff
2 6 1 ffffff
3 6 1 ffffff
4 6 1 ffffff
5 6 1 ffffff
6 6 1 ffffff
7 6 1 ffffff
8 6 1 ffffff
9 6 1 ffffff
0 7 1 ffffff
1 7 1 ffffff
2 7 1 ffffff
3 7 1 ffffff
4 7 1 ffffff
5 7 1 ffffff
6 7 1 ffffff
7 7 1 ffffff
8 7 1 ffffff
9 7 1 ffffff
0 8 1 ffffff
1 8 1 ffffff
2 8 1 ffffff
3 8 1 ffffff
4 8 1 ffffff
5 8 1 ffffff
6 8 1 ffffff
7 8 1 ffffff
8 8 1 ffffff
9 8 1 ffffff
0 9 1 ffffff
1 9 1 ffffff
2 9 1 ffffff
3 9 1 ffffff
4 9 1 ffffff
5 9 1 ffffff
6 9 1 ffffff
7 9 1 ffffff
8 9 1 ffffff
9 9 1 ffffff
0 0 2 ffffff
1 0 2 ffffff
2 0 2 ffffff
3 0 2 ffffff
4 0 2 ffffff
5 0 2 ffffff
6 0 2 ffffff
7 0 2 ffffff
8 0 2 ffffff
9 0 2 ffffff
0 1 2 ffffff
1 1 2 ffffff
2 1 2 ffffff
3 1 2 ffffff
4 1 2 ffffff
5 1 2 ffffff
6 1 2 ffffff
7 1 2 ffffff
8 1 2 ffffff
9 1 2 ffffff
0 2 2 ffffff
1 2 2 ffffff
2 2 2 ffffff
3 2 2 ffffff
4 2 2 ffffff
5 2 2 ffffff
6 2 2 ffffff
7 2 2 ffffff
8 2 2 ffffff
9 2 2 ffffff
0 3 2 ffffff
1 3 2 ffffff
2 3 2 ffffff
3 3 2 ffffff
4 3 2 ffffff
5 3 2 ffffff
6 3 2 ffffff
7 3 2 ffffff
8 3 2 ffffff
9 3 2 ffffff
0 4 2 ffffff
1 4 2 ffffff
2 4 2 ffffff
3 4 2 ffffff
4 4 2 ffffff
5 4 2 ffffff
6 4 2 ffffff
7 4 2 ffffff
8 4 2 ffffff
9 4 2 ffffff
0 5 2 ffffff
1 5 2 ffffff
2 5 2 ffffff
3 5 2 ffffff
4 5 2 ffffff
5 5 2 ffffff
6 5 2 ffffff
7 5 2 ffffff
8 5 2 ffffff
9 5 2 ffffff
0 6 2 ffffff
1 6 2 ffffff
2 6 2 ffffff
3 6 2 ffffff
4 6 2 ffffff
5 6 2 ffffff
6 6 2 ffffff
7 6 2 ffffff
8 6 2 ffffff
9 6 2 ffffff
0 7 2 ffffff
1 7 2 ffffff
2 7 2 ffffff
3 7 2 ffffff
4 7 2 ffffff
5 7 2 ffffff
6 7 2 ffffff
7 7 2 ffffff
8 7 2 ffffff
9 7 2 ffffff
0 8 2 ffffff
1 8 2 ffffff
2 8 2 ffffff
3 8 2 ffffff
4 8 2 ffffff
5 8 2 ffffff
6 8 2 ffffff
7 8 2 ffffff
8 8 2 ffffff
9 8 2 ffffff
0 9 2 ffffff
1 9 2 ffffff
2 9 2 ffffff
3 9 2 ffffff
4 9 2 ffffff
5 9 2 ffffff
6 9 2 ffffff
7 9 2 ffffff
8 9 2 ffffff
9 9 2 ffffff
0 0 3 ffffff
1 0 3 ffffff
2 0 3 ffffff
3 0 3 ffffff
4 0 3 ffffff
5 0 3 ffffff
6 0 3 ffffff
7 0 3 ffffff
8 0 3 ffffff
9 0 3 ffffff
0 1 3 ffffff
1 1 3 ffffff
2 1 3 ffffff
3 1 3 ffffff
4 1 3 ffffff
5 1 3 ffffff
6 1 3 ffffff
7 1 3 ffffff
8 1 3 ffffff
9 1 3 ffffff
0 2 3 ffffff
1 2 3 ffffff
2 2 3 ffffff
3 2 3 ffffff
4 2 3 ffffff
5 2 3 ffffff
6 2 3 ffffff
7 2 3 ffffff
8 2 3 ffffff
9 2 3 ffffff
0 3 3 ffffff
1 3 3 ffffff
2 3 3 ffffff
3 3 3 ffffff
4 3 3 ffffff
5 3 3 ffffff
6 3 3 ffffff
7 3 3 ffffff
8 3 3 ffffff
9 3 3 ffffff
0 4 3 ffffff
1 4 3 ffffff
2 4 3 ffffff
3 4 3 ffffff
4 4 3 ffffff
5 4 3 ffffff
6 4 3 ffffff
7 4 3 ffffff
8 4 3 ffffff
9 4 3 ffffff
0 5 3 ffffff
1 5 3 ffffff
2 5 3 ffffff
3 5 3 ffffff
4 5 3 ffffff
5 5 3 ffffff
6 5 3 ffffff
7 5 3 ffffff
8 5 3 ffffff
9 5 3 ffffff
0 6 3 ffffff
1 6 3 ffffff
2 6 3 ffffff
3 6 3 ffffff
4 6 3 ffffff
5 6 3 ffffff
6 6 3 ffffff
7 6 3 ffffff
8 6 3 ffffff
9 6 3 ffffff
0 7 3 ffffff
1 7 3 ffffff
2 7 3 ffffff
3 7 3 ffffff
4 7 3 ffffff
5 7 3 ffffff
6 7 3 ffffff
7 7 3 ffffff
8 7 3 ffffff
9 7 3 ffffff
0 8 3 ffffff
1 8 3 ffffff
2 8 3 ffffff
3 8 3 ffffff
4 8 3 ffffff
5 8 3 ffffff
6 8 3 ffffff
7 8 3 ffffff
8 8 3 ffffff
9 8 3 ffffff
0 9 3 ffffff
1 9 3 ffffff
2 9 3 ffffff
3 9 3 ffffff
4 9 3 ffffff
5 9 3 ffffff
6 9 3 ffffff
7 9 3 ffffff
8 9 3 ffffff
9 9 3 ffffff
0 0 4 ffffff
1 0 4 ffffff
2 0 4 ffffff
3 0 4 ffffff
4 0 4 ffffff
5 0 4 ffffff
6 0 4 ffffff
7 0 4 ffffff
8 0 4 ffffff
9 0 4 ffffff
0 1 4 ffffff
1 1 4 ffffff
2 1 4 ffffff
3 1 4 ffffff
4 1 4 ffffff
5 1 4 ffffff
6 1 4 ffffff
7 1 4 ffffff
8 1 4 ffffff
9 1 4 ffffff
0 2 4 ffffff
1 2 4 ffffff
2 2 4 ffffff
3 2 4 ffffff
4 2 4 ffffff
5 2 4 ffffff
6 2 4 ffffff
7 2 4 ffffff
8 2 4 ffffff
9 2 4 ffffff
0 3 4 ffffff
1 3 4 ffffff
2 3 4 ffffff
3 3 4 ffffff
4 3 4 ffffff
5 3 4 ffffff
6 3 4 ffffff
7 3 4 ffffff
8 3 4 ffffff
9 3 4 ffffff
0 4 4 ffffff
1 4 4 ffffff
2 4 4 ffffff
3 4 4 ffffff
4 4 4 ffffff
5 4 4 ffffff
6 4 4 ffffff
7 4 4 ffffff
8 4 4 ffffff
9 4 4 ffffff
0 5 4 ffffff
1 5 4 ffffff
2 5 4 ffffff
3 5 4 ffffff
4 5 4 ffffff
5 5 4 ffffff
6 5 4 ffffff
7 5 4 ffffff
8 5 4 ffffff
9 5 4 ffffff
0 6 4 ffffff
1 6 4 ffffff
2 6 4 ffffff
3 6 4 ffffff
4 6 4 ffffff
5 6 4 ffffff
6 6 4 ffffff
7 6 4 ffffff
8 6 4 ffffff
9 6 4 ffffff
0 7 4 ffffff
1 7 4 ffffff
2 7 4 ffffff
3 7 4 ffffff
4 7 4 ffffff
5 7 4 ffffff
6 7 4 ffffff
7 7 4 ffffff
8 7 4 ffffff
9 7 4 ffffff
0 8 4 ffffff
1 8 4 ffffff
2 8 4 ffffff
3 8 4 ffffff
4 8 4 ffffff
5 8 4 ffffff
6 8 4 ffffff
7 8 4 ffffff
8 8 4 ffffff
9 8 4 ffffff
0 9 4 ffffff
1 9 4 ffffff
2 9 4 ffffff
3 9 4 ffffff
4 9 4 ffffff
5 9 4 ffffff
6 9 4 ffffff
7 9 4 ffffff
8 9 4 ffffff
9 9 4 ffffff
